[2024-05-11T15:35:13.867+0000] {local_task_job_runner.py:120} INFO - ::group::Pre task execution logs
[2024-05-11T15:35:13.903+0000] {taskinstance.py:2076} INFO - Dependencies all met for dep_context=non-requeueable deps ti=<TaskInstance: etl_mysql_to_hive_dibimbing_karyawan.load_to_hive manual__2024-05-11T15:28:27.308082+00:00 [queued]>
[2024-05-11T15:35:13.920+0000] {taskinstance.py:2076} INFO - Dependencies all met for dep_context=requeueable deps ti=<TaskInstance: etl_mysql_to_hive_dibimbing_karyawan.load_to_hive manual__2024-05-11T15:28:27.308082+00:00 [queued]>
[2024-05-11T15:35:13.921+0000] {taskinstance.py:2306} INFO - Starting attempt 2 of 2
[2024-05-11T15:35:13.945+0000] {taskinstance.py:2330} INFO - Executing <Task(HiveOperator): load_to_hive> on 2024-05-11 15:28:27.308082+00:00
[2024-05-11T15:35:13.955+0000] {standard_task_runner.py:63} INFO - Started process 6460 to run task
[2024-05-11T15:35:13.962+0000] {standard_task_runner.py:90} INFO - Running: ['***', 'tasks', 'run', 'etl_mysql_to_hive_dibimbing_karyawan', 'load_to_hive', 'manual__2024-05-11T15:28:27.308082+00:00', '--job-id', '691', '--raw', '--subdir', 'DAGS_FOLDER/etl_mysql_to_hive_dibimbing_karyawan.py', '--cfg-path', '/tmp/tmp9fxeqql4']
[2024-05-11T15:35:13.969+0000] {standard_task_runner.py:91} INFO - Job 691: Subtask load_to_hive
[2024-05-11T15:35:14.051+0000] {task_command.py:426} INFO - Running <TaskInstance: etl_mysql_to_hive_dibimbing_karyawan.load_to_hive manual__2024-05-11T15:28:27.308082+00:00 [running]> on host 94409fb18ddd
[2024-05-11T15:35:14.258+0000] {taskinstance.py:2648} INFO - Exporting env vars: AIRFLOW_CTX_DAG_OWNER='***' AIRFLOW_CTX_DAG_ID='etl_mysql_to_hive_dibimbing_karyawan' AIRFLOW_CTX_TASK_ID='load_to_hive' AIRFLOW_CTX_EXECUTION_DATE='2024-05-11T15:28:27.308082+00:00' AIRFLOW_CTX_TRY_NUMBER='2' AIRFLOW_CTX_DAG_RUN_ID='manual__2024-05-11T15:28:27.308082+00:00'
[2024-05-11T15:35:14.263+0000] {taskinstance.py:430} INFO - ::endgroup::
[2024-05-11T15:35:14.264+0000] {hive.py:138} INFO - Executing: 
            INSERT OVERWRITE TABLE dibimbing.karyawan
            SELECT id, nama FROM [[101, '62-8458645009'], [102, '629823849049'], [103, '62-8192744758'], [104, '62-1223349590'], [105, '021057388899']]
        
[2024-05-11T15:35:14.280+0000] {connection.py:274} WARNING - Connection schemes (type: hive_cli) shall not contain '_' according to RFC3986.
[2024-05-11T15:35:14.284+0000] {base.py:84} INFO - Using connection ID 'hive_cli_default' for task execution.
[2024-05-11T15:35:14.285+0000] {hive.py:157} INFO - Passing HiveConf: {'airflow.ctx.dag_owner': '***', 'airflow.ctx.dag_id': 'etl_mysql_to_hive_dibimbing_karyawan', 'airflow.ctx.task_id': 'load_to_hive', 'airflow.ctx.execution_date': '2024-05-11T15:28:27.308082+00:00', 'airflow.ctx.try_number': '2', 'airflow.ctx.dag_run_id': 'manual__2024-05-11T15:28:27.308082+00:00'}
[2024-05-11T15:35:14.289+0000] {hive.py:166} INFO - High Availability not set, setting JDBC url as jdbc:hive2://host.docker.internal:10000/
[2024-05-11T15:35:14.291+0000] {hive.py:309} INFO - beeline -u "jdbc:hive2://host.docker.internal:10000/" -hiveconf ***.ctx.dag_id=etl_mysql_to_hive_dibimbing_karyawan -hiveconf ***.ctx.task_id=load_to_hive -hiveconf ***.ctx.execution_date=2024-05-11T15:28:27.308082+00:00 -hiveconf ***.ctx.try_number=2 -hiveconf ***.ctx.dag_run_id=manual__2024-05-11T15:28:27.308082+00:00 -hiveconf ***.ctx.dag_owner=*** -hiveconf ***.ctx.dag_email= -hiveconf mapred.job.name=Airflow HiveOperator task for 94409fb18ddd.etl_mysql_to_hive_dibimbing_karyawan.load_to_hive.2024-05-11T15:28:27.308082+00:00 -f /tmp/***_hiveop_lpkf59gm/tmpmvrcbyhq
[2024-05-11T15:35:14.472+0000] {hive.py:319} INFO - /home/***/.local/lib/python3.11/site-packages/pyspark/bin/load-spark-env.sh: line 68: ps: command not found
[2024-05-11T15:35:17.849+0000] {hive.py:319} INFO - Connecting to jdbc:hive2://host.docker.internal:10000/
[2024-05-11T15:35:19.252+0000] {hive.py:319} INFO - Connected to: Apache Hive (version 2.3.2)
[2024-05-11T15:35:19.253+0000] {hive.py:319} INFO - Driver: Hive JDBC (version 2.3.9)
[2024-05-11T15:35:19.254+0000] {hive.py:319} INFO - Transaction isolation: TRANSACTION_REPEATABLE_READ
[2024-05-11T15:35:19.501+0000] {hive.py:319} INFO - 0: jdbc:hive2://host.docker.internal:10000/> No rows affected (0.219 seconds)
[2024-05-11T15:35:19.582+0000] {hive.py:319} INFO - 0: jdbc:hive2://host.docker.internal:10000/> 0: jdbc:hive2://host.docker.internal:10000/> . . . . . . . . . . . . . . . . . . . . . .> . . . . . . . . . . . . . . . . . . . . . .> . . . . . . . . . . . . . . . . . . . . . .> . . . . . . . . . . . . . . . . . . . . . .> Error: Error while compiling statement: FAILED: ParseException line 2:21 cannot recognize input near '[' '[' '101' in join source (state=42000,code=40000)
[2024-05-11T15:35:19.604+0000] {hive.py:319} INFO - Closing: 0: jdbc:hive2://host.docker.internal:10000/
[2024-05-11T15:35:19.720+0000] {taskinstance.py:441} INFO - ::group::Post task execution logs
[2024-05-11T15:35:19.749+0000] {taskinstance.py:2905} ERROR - Task failed with exception
Traceback (most recent call last):
  File "/home/airflow/.local/lib/python3.11/site-packages/airflow/models/taskinstance.py", line 465, in _execute_task
    result = _execute_callable(context=context, **execute_callable_kwargs)
             ^^^^^^^^^^^^^^^^^^^^^^^^^^^^^^^^^^^^^^^^^^^^^^^^^^^^^^^^^^^^^
  File "/home/airflow/.local/lib/python3.11/site-packages/airflow/models/taskinstance.py", line 432, in _execute_callable
    return execute_callable(context=context, **execute_callable_kwargs)
           ^^^^^^^^^^^^^^^^^^^^^^^^^^^^^^^^^^^^^^^^^^^^^^^^^^^^^^^^^^^^
  File "/home/airflow/.local/lib/python3.11/site-packages/airflow/models/baseoperator.py", line 400, in wrapper
    return func(self, *args, **kwargs)
           ^^^^^^^^^^^^^^^^^^^^^^^^^^^
  File "/home/airflow/.local/lib/python3.11/site-packages/airflow/providers/apache/hive/operators/hive.py", line 158, in execute
    self.hook.run_cli(hql=self.hql, schema=self.schema, hive_conf=self.hiveconfs)
  File "/home/airflow/.local/lib/python3.11/site-packages/airflow/providers/apache/hive/hooks/hive.py", line 323, in run_cli
    raise AirflowException(stdout)
airflow.exceptions.AirflowException: /home/***/.local/lib/python3.11/site-packages/pyspark/bin/load-spark-env.sh: line 68: ps: command not found
Connecting to jdbc:hive2://host.docker.internal:10000/
Connected to: Apache Hive (version 2.3.2)
Driver: Hive JDBC (version 2.3.9)
Transaction isolation: TRANSACTION_REPEATABLE_READ
0: jdbc:hive2://host.docker.internal:10000/> No rows affected (0.219 seconds)
0: jdbc:hive2://host.docker.internal:10000/> 0: jdbc:hive2://host.docker.internal:10000/> . . . . . . . . . . . . . . . . . . . . . .> . . . . . . . . . . . . . . . . . . . . . .> . . . . . . . . . . . . . . . . . . . . . .> . . . . . . . . . . . . . . . . . . . . . .> Error: Error while compiling statement: FAILED: ParseException line 2:21 cannot recognize input near '[' '[' '101' in join source (state=42000,code=40000)
Closing: 0: jdbc:hive2://host.docker.internal:10000/

[2024-05-11T15:35:19.768+0000] {taskinstance.py:1206} INFO - Marking task as FAILED. dag_id=etl_mysql_to_hive_dibimbing_karyawan, task_id=load_to_hive, run_id=manual__2024-05-11T15:28:27.308082+00:00, execution_date=20240511T152827, start_date=20240511T153513, end_date=20240511T153519
[2024-05-11T15:35:19.806+0000] {standard_task_runner.py:110} ERROR - Failed to execute job 691 for task load_to_hive (/home/***/.local/lib/python3.11/site-packages/pyspark/bin/load-spark-env.sh: line 68: ps: command not found
Connecting to jdbc:hive2://host.docker.internal:10000/
Connected to: Apache Hive (version 2.3.2)
Driver: Hive JDBC (version 2.3.9)
Transaction isolation: TRANSACTION_REPEATABLE_READ
0: jdbc:hive2://host.docker.internal:10000/> No rows affected (0.219 seconds)
0: jdbc:hive2://host.docker.internal:10000/> 0: jdbc:hive2://host.docker.internal:10000/> . . . . . . . . . . . . . . . . . . . . . .> . . . . . . . . . . . . . . . . . . . . . .> . . . . . . . . . . . . . . . . . . . . . .> . . . . . . . . . . . . . . . . . . . . . .> Error: Error while compiling statement: FAILED: ParseException line 2:21 cannot recognize input near '[' '[' '101' in join source (state=42000,code=40000)
Closing: 0: jdbc:hive2://host.docker.internal:10000/
; 6460)
[2024-05-11T15:35:19.852+0000] {local_task_job_runner.py:240} INFO - Task exited with return code 1
[2024-05-11T15:35:19.917+0000] {taskinstance.py:3498} INFO - 0 downstream tasks scheduled from follow-on schedule check
[2024-05-11T15:35:19.932+0000] {local_task_job_runner.py:222} INFO - ::endgroup::
