[2024-07-10T15:26:32.531+0000] {local_task_job_runner.py:120} INFO - ::group::Pre task execution logs
[2024-07-10T15:26:32.596+0000] {taskinstance.py:2076} INFO - Dependencies all met for dep_context=non-requeueable deps ti=<TaskInstance: pet_adoption_dag.load_to_mysql manual__2024-07-10T15:11:33.743623+00:00 [queued]>
[2024-07-10T15:26:32.622+0000] {taskinstance.py:2076} INFO - Dependencies all met for dep_context=requeueable deps ti=<TaskInstance: pet_adoption_dag.load_to_mysql manual__2024-07-10T15:11:33.743623+00:00 [queued]>
[2024-07-10T15:26:32.624+0000] {taskinstance.py:2306} INFO - Starting attempt 4 of 5
[2024-07-10T15:26:32.653+0000] {taskinstance.py:2330} INFO - Executing <Task(PythonOperator): load_to_mysql> on 2024-07-10 15:11:33.743623+00:00
[2024-07-10T15:26:32.662+0000] {standard_task_runner.py:63} INFO - Started process 847 to run task
[2024-07-10T15:26:32.669+0000] {standard_task_runner.py:90} INFO - Running: ['***', 'tasks', 'run', 'pet_adoption_dag', 'load_to_mysql', 'manual__2024-07-10T15:11:33.743623+00:00', '--job-id', '15', '--raw', '--subdir', 'DAGS_FOLDER/pet_adoption_dag.py', '--cfg-path', '/tmp/tmpznoqy2oc']
[2024-07-10T15:26:32.672+0000] {standard_task_runner.py:91} INFO - Job 15: Subtask load_to_mysql
[2024-07-10T15:26:32.772+0000] {task_command.py:426} INFO - Running <TaskInstance: pet_adoption_dag.load_to_mysql manual__2024-07-10T15:11:33.743623+00:00 [running]> on host 9227fc3503c5
[2024-07-10T15:26:32.973+0000] {taskinstance.py:2648} INFO - Exporting env vars: AIRFLOW_CTX_DAG_OWNER='***' AIRFLOW_CTX_DAG_ID='pet_adoption_dag' AIRFLOW_CTX_TASK_ID='load_to_mysql' AIRFLOW_CTX_EXECUTION_DATE='2024-07-10T15:11:33.743623+00:00' AIRFLOW_CTX_TRY_NUMBER='4' AIRFLOW_CTX_DAG_RUN_ID='manual__2024-07-10T15:11:33.743623+00:00'
[2024-07-10T15:26:32.975+0000] {taskinstance.py:430} INFO - ::endgroup::
[2024-07-10T15:26:33.141+0000] {base.py:84} INFO - Using connection ID 'mysql_pet_adoption' for task execution.
[2024-07-10T15:26:33.160+0000] {taskinstance.py:441} INFO - ::group::Post task execution logs
[2024-07-10T15:26:33.162+0000] {taskinstance.py:2905} ERROR - Task failed with exception
Traceback (most recent call last):
  File "/home/airflow/.local/lib/python3.11/site-packages/airflow/models/taskinstance.py", line 465, in _execute_task
    result = _execute_callable(context=context, **execute_callable_kwargs)
             ^^^^^^^^^^^^^^^^^^^^^^^^^^^^^^^^^^^^^^^^^^^^^^^^^^^^^^^^^^^^^
  File "/home/airflow/.local/lib/python3.11/site-packages/airflow/models/taskinstance.py", line 432, in _execute_callable
    return execute_callable(context=context, **execute_callable_kwargs)
           ^^^^^^^^^^^^^^^^^^^^^^^^^^^^^^^^^^^^^^^^^^^^^^^^^^^^^^^^^^^^
  File "/home/airflow/.local/lib/python3.11/site-packages/airflow/models/baseoperator.py", line 401, in wrapper
    return func(self, *args, **kwargs)
           ^^^^^^^^^^^^^^^^^^^^^^^^^^^
  File "/home/airflow/.local/lib/python3.11/site-packages/airflow/operators/python.py", line 235, in execute
    return_value = self.execute_callable()
                   ^^^^^^^^^^^^^^^^^^^^^^^
  File "/home/airflow/.local/lib/python3.11/site-packages/airflow/operators/python.py", line 252, in execute_callable
    return self.python_callable(*self.op_args, **self.op_kwargs)
           ^^^^^^^^^^^^^^^^^^^^^^^^^^^^^^^^^^^^^^^^^^^^^^^^^^^^^
  File "/opt/airflow/dags/pet_adoption_dag.py", line 36, in load_to_mysql
    connection = mysql_hook.get_conn()
                 ^^^^^^^^^^^^^^^^^^^^^
  File "/home/airflow/.local/lib/python3.11/site-packages/airflow/providers/mysql/hooks/mysql.py", line 196, in get_conn
    return MySQLdb.connect(**conn_config)
           ^^^^^^^^^^^^^^^^^^^^^^^^^^^^^^
  File "/home/airflow/.local/lib/python3.11/site-packages/MySQLdb/__init__.py", line 121, in Connect
    return Connection(*args, **kwargs)
           ^^^^^^^^^^^^^^^^^^^^^^^^^^^
  File "/home/airflow/.local/lib/python3.11/site-packages/MySQLdb/connections.py", line 195, in __init__
    super().__init__(*args, **kwargs2)
MySQLdb.OperationalError: (2002, "Can't connect to local server through socket '/run/mysqld/mysqld.sock' (2)")
[2024-07-10T15:26:33.193+0000] {taskinstance.py:1206} INFO - Marking task as UP_FOR_RETRY. dag_id=pet_adoption_dag, task_id=load_to_mysql, run_id=manual__2024-07-10T15:11:33.743623+00:00, execution_date=20240710T151133, start_date=20240710T152632, end_date=20240710T152633
[2024-07-10T15:26:33.224+0000] {standard_task_runner.py:110} ERROR - Failed to execute job 15 for task load_to_mysql ((2002, "Can't connect to local server through socket '/run/mysqld/mysqld.sock' (2)"); 847)
[2024-07-10T15:26:33.244+0000] {local_task_job_runner.py:240} INFO - Task exited with return code 1
[2024-07-10T15:26:33.282+0000] {taskinstance.py:3503} INFO - 0 downstream tasks scheduled from follow-on schedule check
[2024-07-10T15:26:33.286+0000] {local_task_job_runner.py:222} INFO - ::endgroup::
