[2024-07-07T06:49:36.522+0000] {local_task_job_runner.py:120} INFO - ::group::Pre task execution logs
[2024-07-07T06:49:36.621+0000] {taskinstance.py:2076} INFO - Dependencies all met for dep_context=non-requeueable deps ti=<TaskInstance: pet_adoption_etl.extract scheduled__2022-03-03T00:00:00+00:00 [queued]>
[2024-07-07T06:49:36.672+0000] {taskinstance.py:2076} INFO - Dependencies all met for dep_context=requeueable deps ti=<TaskInstance: pet_adoption_etl.extract scheduled__2022-03-03T00:00:00+00:00 [queued]>
[2024-07-07T06:49:36.674+0000] {taskinstance.py:2306} INFO - Starting attempt 1 of 2
[2024-07-07T06:49:36.803+0000] {taskinstance.py:2330} INFO - Executing <Task(PythonOperator): extract> on 2022-03-03 00:00:00+00:00
[2024-07-07T06:49:36.815+0000] {standard_task_runner.py:63} INFO - Started process 1433 to run task
[2024-07-07T06:49:36.827+0000] {standard_task_runner.py:90} INFO - Running: ['***', 'tasks', 'run', 'pet_adoption_etl', 'extract', 'scheduled__2022-03-03T00:00:00+00:00', '--job-id', '397', '--raw', '--subdir', 'DAGS_FOLDER/etl_pet_adoption.py', '--cfg-path', '/tmp/tmpy8bzdc0w']
[2024-07-07T06:49:36.839+0000] {standard_task_runner.py:91} INFO - Job 397: Subtask extract
[2024-07-07T06:49:37.071+0000] {task_command.py:426} INFO - Running <TaskInstance: pet_adoption_etl.extract scheduled__2022-03-03T00:00:00+00:00 [running]> on host 8b51af410d55
[2024-07-07T06:49:37.529+0000] {taskinstance.py:2648} INFO - Exporting env vars: AIRFLOW_CTX_DAG_OWNER='***' AIRFLOW_CTX_DAG_ID='pet_adoption_etl' AIRFLOW_CTX_TASK_ID='extract' AIRFLOW_CTX_EXECUTION_DATE='2022-03-03T00:00:00+00:00' AIRFLOW_CTX_TRY_NUMBER='1' AIRFLOW_CTX_DAG_RUN_ID='scheduled__2022-03-03T00:00:00+00:00'
[2024-07-07T06:49:37.536+0000] {taskinstance.py:430} INFO - ::endgroup::
[2024-07-07T06:49:37.544+0000] {logging_mixin.py:188} INFO - Error in extract: [Errno 2] No such file or directory: 'C:\\Users\\Indah Permata\\Documents\\dbimbing_final_project\\data\\pet_adoption_data.csv'
[2024-07-07T06:49:37.547+0000] {taskinstance.py:441} INFO - ::group::Post task execution logs
[2024-07-07T06:49:37.555+0000] {taskinstance.py:2905} ERROR - Task failed with exception
Traceback (most recent call last):
  File "/home/airflow/.local/lib/python3.11/site-packages/airflow/models/taskinstance.py", line 465, in _execute_task
    result = _execute_callable(context=context, **execute_callable_kwargs)
             ^^^^^^^^^^^^^^^^^^^^^^^^^^^^^^^^^^^^^^^^^^^^^^^^^^^^^^^^^^^^^
  File "/home/airflow/.local/lib/python3.11/site-packages/airflow/models/taskinstance.py", line 432, in _execute_callable
    return execute_callable(context=context, **execute_callable_kwargs)
           ^^^^^^^^^^^^^^^^^^^^^^^^^^^^^^^^^^^^^^^^^^^^^^^^^^^^^^^^^^^^
  File "/home/airflow/.local/lib/python3.11/site-packages/airflow/models/baseoperator.py", line 401, in wrapper
    return func(self, *args, **kwargs)
           ^^^^^^^^^^^^^^^^^^^^^^^^^^^
  File "/home/airflow/.local/lib/python3.11/site-packages/airflow/operators/python.py", line 235, in execute
    return_value = self.execute_callable()
                   ^^^^^^^^^^^^^^^^^^^^^^^
  File "/home/airflow/.local/lib/python3.11/site-packages/airflow/operators/python.py", line 252, in execute_callable
    return self.python_callable(*self.op_args, **self.op_kwargs)
           ^^^^^^^^^^^^^^^^^^^^^^^^^^^^^^^^^^^^^^^^^^^^^^^^^^^^^
  File "/opt/airflow/dags/etl_pet_adoption.py", line 14, in extract
    df = pd.read_csv(FILE_PATH)
         ^^^^^^^^^^^^^^^^^^^^^^
  File "/home/airflow/.local/lib/python3.11/site-packages/pandas/io/parsers/readers.py", line 948, in read_csv
    return _read(filepath_or_buffer, kwds)
           ^^^^^^^^^^^^^^^^^^^^^^^^^^^^^^^
  File "/home/airflow/.local/lib/python3.11/site-packages/pandas/io/parsers/readers.py", line 611, in _read
    parser = TextFileReader(filepath_or_buffer, **kwds)
             ^^^^^^^^^^^^^^^^^^^^^^^^^^^^^^^^^^^^^^^^^^
  File "/home/airflow/.local/lib/python3.11/site-packages/pandas/io/parsers/readers.py", line 1448, in __init__
    self._engine = self._make_engine(f, self.engine)
                   ^^^^^^^^^^^^^^^^^^^^^^^^^^^^^^^^^
  File "/home/airflow/.local/lib/python3.11/site-packages/pandas/io/parsers/readers.py", line 1705, in _make_engine
    self.handles = get_handle(
                   ^^^^^^^^^^^
  File "/home/airflow/.local/lib/python3.11/site-packages/pandas/io/common.py", line 863, in get_handle
    handle = open(
             ^^^^^
FileNotFoundError: [Errno 2] No such file or directory: 'C:\\Users\\Indah Permata\\Documents\\dbimbing_final_project\\data\\pet_adoption_data.csv'
[2024-07-07T06:49:37.612+0000] {taskinstance.py:1206} INFO - Marking task as UP_FOR_RETRY. dag_id=pet_adoption_etl, task_id=extract, run_id=scheduled__2022-03-03T00:00:00+00:00, execution_date=20220303T000000, start_date=20240707T064936, end_date=20240707T064937
[2024-07-07T06:49:37.687+0000] {standard_task_runner.py:110} ERROR - Failed to execute job 397 for task extract ([Errno 2] No such file or directory: 'C:\\Users\\Indah Permata\\Documents\\dbimbing_final_project\\data\\pet_adoption_data.csv'; 1433)
[2024-07-07T06:49:37.780+0000] {local_task_job_runner.py:240} INFO - Task exited with return code 1
[2024-07-07T06:49:37.878+0000] {taskinstance.py:3503} INFO - 0 downstream tasks scheduled from follow-on schedule check
[2024-07-07T06:49:37.893+0000] {local_task_job_runner.py:222} INFO - ::endgroup::
