[2024-07-12T13:59:26.406+0000] {local_task_job_runner.py:120} INFO - ::group::Pre task execution logs
[2024-07-12T13:59:26.460+0000] {taskinstance.py:2076} INFO - Dependencies all met for dep_context=non-requeueable deps ti=<TaskInstance: pet_adoption_dag.load_to_mysql scheduled__2024-07-11T00:00:00+00:00 [queued]>
[2024-07-12T13:59:26.473+0000] {taskinstance.py:2076} INFO - Dependencies all met for dep_context=requeueable deps ti=<TaskInstance: pet_adoption_dag.load_to_mysql scheduled__2024-07-11T00:00:00+00:00 [queued]>
[2024-07-12T13:59:26.475+0000] {taskinstance.py:2306} INFO - Starting attempt 1 of 2
[2024-07-12T13:59:26.516+0000] {taskinstance.py:2330} INFO - Executing <Task(PythonOperator): load_to_mysql> on 2024-07-11 00:00:00+00:00
[2024-07-12T13:59:26.524+0000] {standard_task_runner.py:63} INFO - Started process 66 to run task
[2024-07-12T13:59:26.528+0000] {standard_task_runner.py:90} INFO - Running: ['***', 'tasks', 'run', 'pet_adoption_dag', 'load_to_mysql', 'scheduled__2024-07-11T00:00:00+00:00', '--job-id', '22', '--raw', '--subdir', 'DAGS_FOLDER/pet_adoption_dag.py', '--cfg-path', '/tmp/tmp2sp8msue']
[2024-07-12T13:59:26.530+0000] {standard_task_runner.py:91} INFO - Job 22: Subtask load_to_mysql
[2024-07-12T13:59:26.648+0000] {task_command.py:426} INFO - Running <TaskInstance: pet_adoption_dag.load_to_mysql scheduled__2024-07-11T00:00:00+00:00 [running]> on host 9227fc3503c5
[2024-07-12T13:59:26.846+0000] {taskinstance.py:2648} INFO - Exporting env vars: AIRFLOW_CTX_DAG_OWNER='***' AIRFLOW_CTX_DAG_ID='pet_adoption_dag' AIRFLOW_CTX_TASK_ID='load_to_mysql' AIRFLOW_CTX_EXECUTION_DATE='2024-07-11T00:00:00+00:00' AIRFLOW_CTX_TRY_NUMBER='1' AIRFLOW_CTX_DAG_RUN_ID='scheduled__2024-07-11T00:00:00+00:00'
[2024-07-12T13:59:26.848+0000] {taskinstance.py:430} INFO - ::endgroup::
[2024-07-12T13:59:26.974+0000] {base.py:84} INFO - Using connection ID 'mysql_pet_adoption' for task execution.
[2024-07-12T13:59:27.010+0000] {taskinstance.py:441} INFO - ::group::Post task execution logs
[2024-07-12T13:59:27.011+0000] {taskinstance.py:2905} ERROR - Task failed with exception
Traceback (most recent call last):
  File "/home/airflow/.local/lib/python3.11/site-packages/airflow/models/taskinstance.py", line 465, in _execute_task
    result = _execute_callable(context=context, **execute_callable_kwargs)
             ^^^^^^^^^^^^^^^^^^^^^^^^^^^^^^^^^^^^^^^^^^^^^^^^^^^^^^^^^^^^^
  File "/home/airflow/.local/lib/python3.11/site-packages/airflow/models/taskinstance.py", line 432, in _execute_callable
    return execute_callable(context=context, **execute_callable_kwargs)
           ^^^^^^^^^^^^^^^^^^^^^^^^^^^^^^^^^^^^^^^^^^^^^^^^^^^^^^^^^^^^
  File "/home/airflow/.local/lib/python3.11/site-packages/airflow/models/baseoperator.py", line 401, in wrapper
    return func(self, *args, **kwargs)
           ^^^^^^^^^^^^^^^^^^^^^^^^^^^
  File "/home/airflow/.local/lib/python3.11/site-packages/airflow/operators/python.py", line 235, in execute
    return_value = self.execute_callable()
                   ^^^^^^^^^^^^^^^^^^^^^^^
  File "/home/airflow/.local/lib/python3.11/site-packages/airflow/operators/python.py", line 252, in execute_callable
    return self.python_callable(*self.op_args, **self.op_kwargs)
           ^^^^^^^^^^^^^^^^^^^^^^^^^^^^^^^^^^^^^^^^^^^^^^^^^^^^^
  File "/opt/airflow/dags/pet_adoption_dag.py", line 36, in load_to_mysql
    connection = mysql_hook.get_conn()
                 ^^^^^^^^^^^^^^^^^^^^^
  File "/home/airflow/.local/lib/python3.11/site-packages/airflow/providers/mysql/hooks/mysql.py", line 196, in get_conn
    return MySQLdb.connect(**conn_config)
           ^^^^^^^^^^^^^^^^^^^^^^^^^^^^^^
  File "/home/airflow/.local/lib/python3.11/site-packages/MySQLdb/__init__.py", line 121, in Connect
    return Connection(*args, **kwargs)
           ^^^^^^^^^^^^^^^^^^^^^^^^^^^
  File "/home/airflow/.local/lib/python3.11/site-packages/MySQLdb/connections.py", line 195, in __init__
    super().__init__(*args, **kwargs2)
MySQLdb.OperationalError: (2002, "Can't connect to local server through socket '/run/mysqld/mysqld.sock' (2)")
[2024-07-12T13:59:27.030+0000] {taskinstance.py:1206} INFO - Marking task as UP_FOR_RETRY. dag_id=pet_adoption_dag, task_id=load_to_mysql, run_id=scheduled__2024-07-11T00:00:00+00:00, execution_date=20240711T000000, start_date=20240712T135926, end_date=20240712T135927
[2024-07-12T13:59:27.068+0000] {standard_task_runner.py:110} ERROR - Failed to execute job 22 for task load_to_mysql ((2002, "Can't connect to local server through socket '/run/mysqld/mysqld.sock' (2)"); 66)
[2024-07-12T13:59:27.109+0000] {local_task_job_runner.py:240} INFO - Task exited with return code 1
[2024-07-12T13:59:27.141+0000] {taskinstance.py:3503} INFO - 0 downstream tasks scheduled from follow-on schedule check
[2024-07-12T13:59:27.144+0000] {local_task_job_runner.py:222} INFO - ::endgroup::
